I'm sorry, but an uncaught exception occurred.

While running game code:
  File "game/scripts/battle.rpy", line 80, in script call
    call hero_skill from _call_hero_skill_2
  File "game/scripts/skills.rpy", line 35, in script call
    call hero_skill_animation from _call_hero_skill_animation_1
  File "game/scripts/skills.rpy", line 185, in script
    if(enemy == "enemy_1"):
  File "game/scripts/skills.rpy", line 185, in <module>
    if(enemy == "enemy_1"):
NameError: name 'enemy' is not defined

-- Full Traceback ------------------------------------------------------------

Full traceback:
  File "game/scripts/battle.rpy", line 80, in script call
    call hero_skill from _call_hero_skill_2
  File "game/scripts/skills.rpy", line 35, in script call
    call hero_skill_animation from _call_hero_skill_animation_1
  File "game/scripts/skills.rpy", line 185, in script
    if(enemy == "enemy_1"):
  File "/home/gerald/Desktop/Renpy/renpy-8.0.3-sdk/renpy/ast.py", line 2115, in execute
    if renpy.python.py_eval(condition):
  File "/home/gerald/Desktop/Renpy/renpy-8.0.3-sdk/renpy/python.py", line 1092, in py_eval
    return py_eval_bytecode(code, globals, locals)
  File "/home/gerald/Desktop/Renpy/renpy-8.0.3-sdk/renpy/python.py", line 1085, in py_eval_bytecode
    return eval(bytecode, globals, locals)
  File "game/scripts/skills.rpy", line 185, in <module>
    if(enemy == "enemy_1"):
NameError: name 'enemy' is not defined

Linux-5.15.0-56-generic-x86_64-with-glibc2.35 x86_64
Ren'Py 8.0.3.22090809
HERO 1.0
Fri Dec  9 18:33:50 2022
